Workbook

Sheet Por Recursos
B1: Presupuesto de Proyecto | F1: Cultura X
B2: Elaborado por: Cultura X | E2: % Reserva de Contingencia | G2: 0.3
B3: Scrum Master: Ricardo Gonzalez | E3: Presupuesto | F3: Reservas | G3: Total
B4: Fecha de Inicio: 15/08/2025 | D4: Total | E4: =G7 -> 3095694 | F4: =E4*G2 -> 928708.2 | G4: =E4+F4 -> 4024402.2
B6: Categoría | C6: Recurso | E6: Tipo de Unidades | F6: Tasa | G6: Presupuesto
B7: Costos Directos | G7: =G8+G12 -> 3095694
B8: Labor (Personal) | G8: =SUM(G9:G11) -> 2714754
C9: Ricardo Gonzalez | E9: =VLOOKUP(C9,Datos!$B$8:$E$15,3,) -> Horas / Jornadas | F9: =VLOOKUP(C9,Datos!$B$8:$E$13,4,) -> 7630 | G9: =SUMIF('Presupuesto Detallado'!D:D, "Ricardo Gonzalez", 'Presupuesto Detallado'!I:I) -> 904918
C10: Bastian Vidal | E10: =VLOOKUP(C10,Datos!$B$8:$E$15,3,) -> Horas / Jornadas | F10: =VLOOKUP(C10,Datos!$B$8:$E$13,4,) -> 7630 | G10: =SUMIF('Presupuesto Detallado'!D:D, "Bastian Vidal", 'Presupuesto Detallado'!I:I) -> 904918
C11: Rodrigo Gonzalez | E11: =VLOOKUP(C11,Datos!$B$8:$E$15,3,) -> Horas / Jornadas | F11: =VLOOKUP(C11,Datos!$B$8:$E$13,4,) -> 7630 | G11: =SUMIF('Presupuesto Detallado'!D:D, "Rodrigo Gonzalez", 'Presupuesto Detallado'!I:I) -> 904918
B12: Licencias | G12: =SUM(G13:G17) -> 380940
C13: Microsoft 365 | E13: =VLOOKUP(C13,Datos!$B$8:$E$15,3,) -> Cantidad | F13: =VLOOKUP(C13,Datos!$B$8:$E$15,4,) -> 8490 | G13: =SUMIF('Presupuesto Detallado'!D:D, "Microsoft 365", 'Presupuesto Detallado'!I:I) -> 50940
C14: Trello | E14: =VLOOKUP(C14,Datos!$B$8:$E$15,3,) -> Cantidad | F14: =VLOOKUP(C14,Datos!$B$8:$E$15,4,) -> 5000 | G14: =SUMIF('Presupuesto Detallado'!D:D, "Trello", 'Presupuesto Detallado'!I:I) -> 95000
C15: Firebase | E15: =VLOOKUP(C15,Datos!$B$8:$E$15,3,) -> Cantidad | F15: =VLOOKUP(C15,Datos!$B$8:$E$13,4,) -> 15000 | G15: =SUMIF('Presupuesto Detallado'!D:D, "Firebase", 'Presupuesto Detallado'!I:I) -> 195000
C16: Dominio | E16: =VLOOKUP(C16,Datos!$B$8:$E$15,3,) -> Cantidad | F16: =VLOOKUP(C16,Datos!$B$8:$E$13,4,) -> 10000 | G16: =SUMIF('Presupuesto Detallado'!D:D, "Dominio", 'Presupuesto Detallado'!I:I) -> 10000
C17: Hosting | E17: =VLOOKUP(C17,Datos!$B$8:$E$15,3,) -> Cantidad | F17: =VLOOKUP(C17,Datos!$B$8:$E$13,4,) -> 30000 | G17: =SUMIF('Presupuesto Detallado'!D:D, "Hosting", 'Presupuesto Detallado'!I:I) -> 30000

Sheet Presupuesto Detallado
B1: Presupuesto de Proyecto | G1: Cultura X
B2: Elaborado por: Cultura X | G2: % Reserva de Contingencia | I2: 0.3
B3: Scrum Master: Ricardo Gonzalez | G3: Presupuesto | H3: Reservas | I3: Total
B4: Fecha de Inicio: 15/08/2025 | E4: Total | G4: =I7+I88 -> 3095694 | H4: =G4*I2 -> 928708.2 | I4: =G4+H4 -> 4024402.2
B6: Código | C6: Tarea / Actividad | D6: Elemento | E6: Tipo de Recurso | F6: Tipo de Unidades | G6: Unidades | H6: Tasa | I6: Presupuesto
B7: 1 | C7: Desarrollo | I7: =I8+I16+I22+I28+I34+I40+I46+I52+I58+I64+I70+I76+I82 -> 2694294
B8: 1.1 | C8: Épica 1: Autenticación y gestión de usuarios | I8: =SUM(I9:I15) -> 364437
D9: Ricardo Gonzalez | E9: =IFERROR(VLOOKUP(D9,Datos!$B$8:$E$15,2,),"") -> Labor (Personal) | F9: =IFERROR(VLOOKUP(D9,Datos!$B$8:$E$15,3,),"") -> Horas / Jornadas | G9: 13.3 | H9: {=XLOOKUP(D9,Datos!B:B,Datos!E:E,"Error",0)} -> 7630 | I9: =G9*H9 -> 101479
D10: Bastian Vidal | E10: =IFERROR(VLOOKUP(D10,Datos!$B$8:$E$15,2,),"") -> Labor (Personal) | F10: =IFERROR(VLOOKUP(D10,Datos!$B$8:$E$15,3,),"") -> Horas / Jornadas | G10: 13.3 | H10: {=XLOOKUP(D10,Datos!B:B,Datos!E:E,"Error",0)} -> 7630 | I10: =G10*H10 -> 101479
D11: Rodrigo Gonzalez | E11: =IFERROR(VLOOKUP(D11,Datos!$B$8:$E$15,2,),"") -> Labor (Personal) | F11: =IFERROR(VLOOKUP(D11,Datos!$B$8:$E$15,3,),"") -> Horas / Jornadas | G11: 13.3 | H11: {=XLOOKUP(D11,Datos!B:B,Datos!E:E,"Error",0)} -> 7630 | I11: =G11*H11 -> 101479
D12: Firebase | E12: =IFERROR(VLOOKUP(D12,Datos!$B$8:$E$15,2,),"") -> Licencias | F12: =IFERROR(VLOOKUP(D12,Datos!$B$8:$E$15,3,),"") -> Cantidad | G12: 1 | H12: {=XLOOKUP(D12,Datos!B:B,Datos!E:E,"Error",0)} -> 15000 | I12: =G12*H12 -> 15000
D13: Trello | E13: =IFERROR(VLOOKUP(D13,Datos!$B$8:$E$15,2,),"") -> Licencias | F13: =IFERROR(VLOOKUP(D13,Datos!$B$8:$E$15,3,),"") -> Cantidad | G13: 1 | H13: {=XLOOKUP(D13,Datos!B:B,Datos!E:E,"Error",0)} -> 5000 | I13: =G13*H13 -> 5000
D14: Hosting | E14: =IFERROR(VLOOKUP(D14,Datos!$B$8:$E$15,2,),"") -> Licencias | F14: =IFERROR(VLOOKUP(D14,Datos!$B$8:$E$15,3,),"") -> Cantidad | G14: 1 | H14: {=XLOOKUP(D14,Datos!B:B,Datos!E:E,"Error",0)} -> 30000 | I14: =G14*H14 -> 30000
D15: Dominio | E15: =IFERROR(VLOOKUP(D15,Datos!$B$8:$E$15,2,),"") -> Licencias | F15: =IFERROR(VLOOKUP(D15,Datos!$B$8:$E$15,3,),"") -> Cantidad | G15: 1 | H15: {=XLOOKUP(D15,Datos!B:B,Datos!E:E,"Error",0)} -> 10000 | I15: =G15*H15 -> 10000
B16: 1.2 | C16: Épica 2: Contenido cultural y vistas por categoría | E16: =IFERROR(VLOOKUP(D16,Datos!$B$8:$E$15,2,),"") | F16: =IFERROR(VLOOKUP(D16,Datos!$B$8:$E$15,3,),"") | I16: =SUM(I17:I21) -> 324437
D17: Ricardo Gonzalez | E17: =IFERROR(VLOOKUP(D17,Datos!$B$8:$E$15,2,),"") -> Labor (Personal) | F17: =IFERROR(VLOOKUP(D17,Datos!$B$8:$E$15,3,),"") -> Horas / Jornadas | G17: 13.3 | H17: {=XLOOKUP(D17,Datos!B:B,Datos!E:E,"Error",0)} -> 7630 | I17: =G17*H17 -> 101479
D18: Bastian Vidal | E18: =IFERROR(VLOOKUP(D18,Datos!$B$8:$E$15,2,),"") -> Labor (Personal) | F18: =IFERROR(VLOOKUP(D18,Datos!$B$8:$E$15,3,),"") -> Horas / Jornadas | G18: 13.3 | H18: {=XLOOKUP(D18,Datos!B:B,Datos!E:E,"Error",0)} -> 7630 | I18: =G18*H18 -> 101479
D19: Rodrigo Gonzalez | E19: =IFERROR(VLOOKUP(D19,Datos!$B$8:$E$15,2,),"") -> Labor (Personal) | F19: =IFERROR(VLOOKUP(D19,Datos!$B$8:$E$15,3,),"") -> Horas / Jornadas | G19: 13.3 | H19: {=XLOOKUP(D19,Datos!B:B,Datos!E:E,"Error",0)} -> 7630 | I19: =G19*H19 -> 101479
D20: Trello | E20: =IFERROR(VLOOKUP(D20,Datos!$B$8:$E$15,2,),"") -> Licencias | F20: =IFERROR(VLOOKUP(D20,Datos!$B$8:$E$15,3,),"") -> Cantidad | G20: 1 | H20: {=XLOOKUP(D20,Datos!B:B,Datos!E:E,"Error",0)} -> 5000 | I20: =G20*H20 -> 5000
D21: Firebase | E21: =IFERROR(VLOOKUP(D21,Datos!$B$8:$E$15,2,),"") -> Licencias | F21: =IFERROR(VLOOKUP(D21,Datos!$B$8:$E$15,3,),"") -> Cantidad | G21: 1 | H21: {=XLOOKUP(D21,Datos!B:B,Datos!E:E,"Error",0)} -> 15000 | I21: =G21*H21 -> 15000
B22: 1.3 | C22: Épica 3: Sistema de reseñas y calificaciones | E22: =IFERROR(VLOOKUP(D22,Datos!$B$8:$E$15,2,),"") | F22: =IFERROR(VLOOKUP(D22,Datos!$B$8:$E$15,3,),"") | I22: =SUM(I23:I27) -> 324437
D23: Ricardo Gonzalez | E23: =IFERROR(VLOOKUP(D23,Datos!$B$8:$E$15,2,),"") -> Labor (Personal) | F23: =IFERROR(VLOOKUP(D23,Datos!$B$8:$E$15,3,),"") -> Horas / Jornadas | G23: 13.3 | H23: {=XLOOKUP(D23,Datos!B:B,Datos!E:E,"Error",0)} -> 7630 | I23: =G23*H23 -> 101479
D24: Bastian Vidal | E24: =IFERROR(VLOOKUP(D24,Datos!$B$8:$E$15,2,),"") -> Labor (Personal) | F24: =IFERROR(VLOOKUP(D24,Datos!$B$8:$E$15,3,),"") -> Horas / Jornadas | G24: 13.3 | H24: {=XLOOKUP(D24,Datos!B:B,Datos!E:E,"Error",0)} -> 7630 | I24: =G24*H24 -> 101479
D25: Rodrigo Gonzalez | E25: =IFERROR(VLOOKUP(D25,Datos!$B$8:$E$15,2,),"") -> Labor (Personal) | F25: =IFERROR(VLOOKUP(D25,Datos!$B$8:$E$15,3,),"") -> Horas / Jornadas | G25: 13.3 | H25: {=XLOOKUP(D25,Datos!B:B,Datos!E:E,"Error",0)} -> 7630 | I25: =G25*H25 -> 101479
D26: Trello | E26: =IFERROR(VLOOKUP(D26,Datos!$B$8:$E$15,2,),"") -> Licencias | F26: =IFERROR(VLOOKUP(D26,Datos!$B$8:$E$15,3,),"") -> Cantidad | G26: 1 | H26: {=XLOOKUP(D26,Datos!B:B,Datos!E:E,"Error",0)} -> 5000 | I26: =G26*H26 -> 5000
D27: Firebase | E27: =IFERROR(VLOOKUP(D27,Datos!$B$8:$E$15,2,),"") -> Licencias | F27: =IFERROR(VLOOKUP(D27,Datos!$B$8:$E$15,3,),"") -> Cantidad | G27: 1 | H27: {=XLOOKUP(D27,Datos!B:B,Datos!E:E,"Error",0)} -> 15000 | I27: =G27*H27 -> 15000
B28: 1.4 | C28: Épica 4: Perfil de usuario | E28: =IFERROR(VLOOKUP(D28,Datos!$B$8:$E$15,2,),"") | F28: =IFERROR(VLOOKUP(D28,Datos!$B$8:$E$15,3,),"") | I28: =SUM(I29:I33) -> 171074
D29: Ricardo Gonzalez | E29: =IFERROR(VLOOKUP(D29,Datos!$B$8:$E$15,2,),"") -> Labor (Personal) | F29: =IFERROR(VLOOKUP(D29,Datos!$B$8:$E$15,3,),"") -> Horas / Jornadas | G29: 6.6 | H29: {=XLOOKUP(D29,Datos!B:B,Datos!E:E,"Error",0)} -> 7630 | I29: =G29*H29 -> 50358
D30: Bastian Vidal | E30: =IFERROR(VLOOKUP(D30,Datos!$B$8:$E$15,2,),"") -> Labor (Personal) | F30: =IFERROR(VLOOKUP(D30,Datos!$B$8:$E$15,3,),"") -> Horas / Jornadas | G30: 6.6 | H30: {=XLOOKUP(D30,Datos!B:B,Datos!E:E,"Error",0)} -> 7630 | I30: =G30*H30 -> 50358
D31: Rodrigo Gonzalez | E31: =IFERROR(VLOOKUP(D31,Datos!$B$8:$E$15,2,),"") -> Labor (Personal) | F31: =IFERROR(VLOOKUP(D31,Datos!$B$8:$E$15,3,),"") -> Horas / Jornadas | G31: 6.6 | H31: {=XLOOKUP(D31,Datos!B:B,Datos!E:E,"Error",0)} -> 7630 | I31: =G31*H31 -> 50358
D32: Trello | E32: =IFERROR(VLOOKUP(D32,Datos!$B$8:$E$15,2,),"") -> Licencias | F32: =IFERROR(VLOOKUP(D32,Datos!$B$8:$E$15,3,),"") -> Cantidad | G32: 1 | H32: {=XLOOKUP(D32,Datos!B:B,Datos!E:E,"Error",0)} -> 5000 | I32: =G32*H32 -> 5000
D33: Firebase | E33: =IFERROR(VLOOKUP(D33,Datos!$B$8:$E$15,2,),"") -> Licencias | F33: =IFERROR(VLOOKUP(D33,Datos!$B$8:$E$15,3,),"") -> Cantidad | G33: 1 | H33: {=XLOOKUP(D33,Datos!B:B,Datos!E:E,"Error",0)} -> 15000 | I33: =G33*H33 -> 15000
B34: 1.5 | C34: Épica 5: Optimización y mantenimiento | E34: =IFERROR(VLOOKUP(D34,Datos!$B$8:$E$15,2,),"") | F34: =IFERROR(VLOOKUP(D34,Datos!$B$8:$E$15,3,),"") | I34: =SUM(I35:I39) -> 171074
D35: Ricardo Gonzalez | E35: =IFERROR(VLOOKUP(D35,Datos!$B$8:$E$15,2,),"") -> Labor (Personal) | F35: =IFERROR(VLOOKUP(D35,Datos!$B$8:$E$15,3,),"") -> Horas / Jornadas | G35: 6.6 | H35: {=XLOOKUP(D35,Datos!B:B,Datos!E:E,"Error",0)} -> 7630 | I35: =G35*H35 -> 50358
D36: Bastian Vidal | E36: =IFERROR(VLOOKUP(D36,Datos!$B$8:$E$15,2,),"") -> Labor (Personal) | F36: =IFERROR(VLOOKUP(D36,Datos!$B$8:$E$15,3,),"") -> Horas / Jornadas | G36: 6.6 | H36: {=XLOOKUP(D36,Datos!B:B,Datos!E:E,"Error",0)} -> 7630 | I36: =G36*H36 -> 50358
D37: Rodrigo Gonzalez | E37: =IFERROR(VLOOKUP(D37,Datos!$B$8:$E$15,2,),"") -> Labor (Personal) | F37: =IFERROR(VLOOKUP(D37,Datos!$B$8:$E$15,3,),"") -> Horas / Jornadas | G37: 6.6 | H37: {=XLOOKUP(D37,Datos!B:B,Datos!E:E,"Error",0)} -> 7630 | I37: =G37*H37 -> 50358
D38: Trello | E38: =IFERROR(VLOOKUP(D38,Datos!$B$8:$E$15,2,),"") -> Licencias | F38: =IFERROR(VLOOKUP(D38,Datos!$B$8:$E$15,3,),"") -> Cantidad | G38: 1 | H38: {=XLOOKUP(D38,Datos!B:B,Datos!E:E,"Error",0)} -> 5000 | I38: =G38*H38 -> 5000
D39: Firebase | E39: =IFERROR(VLOOKUP(D39,Datos!$B$8:$E$15,2,),"") -> Licencias | F39: =IFERROR(VLOOKUP(D39,Datos!$B$8:$E$15,3,),"") -> Cantidad | G39: 1 | H39: {=XLOOKUP(D39,Datos!B:B,Datos!E:E,"Error",0)} -> 15000 | I39: =G39*H39 -> 15000
B40: 1.6 | C40: Épica 6: Publicidad y monetización | E40: =IFERROR(VLOOKUP(D40,Datos!$B$8:$E$15,2,),"") | F40: =IFERROR(VLOOKUP(D40,Datos!$B$8:$E$15,3,),"") | I40: =SUM(I41:I45) -> 171074
D41: Ricardo Gonzalez | E41: =IFERROR(VLOOKUP(D41,Datos!$B$8:$E$15,2,),"") -> Labor (Personal) | F41: =IFERROR(VLOOKUP(D41,Datos!$B$8:$E$15,3,),"") -> Horas / Jornadas | G41: 6.6 | H41: {=XLOOKUP(D41,Datos!B:B,Datos!E:E,"Error",0)} -> 7630 | I41: =G41*H41 -> 50358
...

Sheet Datos
B1: Presupuesto de Proyecto | D1: [Nombre de la Compañía / Logo]
B2: Elaborado por: Cultura X
B3: Scrum Master: Ricardo Gonzalez
B4: Fecha de Inicio: 15/08/2025
B6: Elemento | C6: Tipo de Recurso | D6: Tipo de Unidades | E6: Tasa
B8: Rodrigo Gonzalez | C8: Labor (Personal) | D8: Horas / Jornadas | E8: 7630
B9: Ricardo Gonzalez | C9: Labor (Personal) | D9: Horas / Jornadas | E9: 7630
B10: Bastian Vidal | C10: Labor (Personal) | D10: Horas / Jornadas | E10: 7630
B11: Firebase | C11: Licencias | D11: Cantidad | E11: 15000
B12: Hosting | C12: Licencias | D12: Cantidad | E12: 30000
B13: Dominio | C13: Licencias | D13: Cantidad | E13: 10000
B14: Microsoft 365 | C14: Licencias | D14: Cantidad | E14: 8490
B15: Trello | C15: Licencias | D15: Cantidad | E15: 5000
